Workbook

Sheet Operations Data
A1: Operation ID | B1: Reference ID | C1: Facility | D1: Department | E1: Process Type | F1: Item Category | G1: Quantity | H1: Status | I1: Request Date | J1: Completion Date | L1: Operation ID sequence validation | M1: Status/Completion Date validation | N1: Reference ID Check | O1: Facility Check | P1: Department Check | Q1: Process Type Check | R1: Item Category Check | S1: Overall Validation
A2: OP001 | B2: REF001 | C2: Kolkata | D2: Operations | E2: Inventory Review | F2: Raw Materials | G2: 120 | H2: Completed | I2: 46027 | J2: 46028 | L2: =IF(A2="OP"&TEXT(ROW()-1,"000"),"OK","CHECK") -> OK | M2: =IF(OR(AND(H2="Completed",J2<>""),AND(OR(H2="Pending",H2="In Progress"),J2="")),"OK","CHECK") -> OK | N2: =IFERROR(IF(VLOOKUP(B2,'Reference Data'!$A$2:$F$26,1,FALSE)=B2,"OK","CHECK"),"MISSING") -> OK | O2: =IFERROR(IF(C2=VLOOKUP(B2,'Reference Data'!$A$2:$F$26,2,FALSE),"OK","CHECK"),"MISSING") -> OK | P2: =IFERROR(IF(D2=VLOOKUP(B2,'Reference Data'!$A$2:$F$26,3,FALSE),"OK","CHECK"),"MISSING") -> OK | Q2: =IFERROR(IF(E2=VLOOKUP(B2,'Reference Data'!$A$2:$F$26,4,FALSE),"OK","CHECK"),"MISSING") -> OK | R2: =IFERROR(IF(F2=VLOOKUP(B2,'Reference Data'!$A$2:$F$26,5,FALSE),"OK","CHECK"),"MISSING") -> OK | S2: =IF(AND(L2="OK",M2="OK",N2="OK",O2="OK",P2="OK",Q2="OK",R2="OK"),"OK","REVIEW") -> OK
A3: OP002 | B3: REF002 | C3: Kolkata | D3: Quality | E3: Quality Inspection | F3: Finished Goods | G3: 85 | H3: Completed | I3: 46030 | J3: 46031 | L3: =IF(A3="OP"&TEXT(ROW()-1,"000"),"OK","CHECK") -> OK | M3: =IF(OR(AND(H3="Completed",J3<>""),AND(OR(H3="Pending",H3="In Progress"),J3="")),"OK","CHECK") -> OK | N3: =IFERROR(IF(VLOOKUP(B3,'Reference Data'!$A$2:$F$26,1,FALSE)=B3,"OK","CHECK"),"MISSING") -> OK | O3: =IFERROR(IF(C3=VLOOKUP(B3,'Reference Data'!$A$2:$F$26,2,FALSE),"OK","CHECK"),"MISSING") -> OK | P3: =IFERROR(IF(D3=VLOOKUP(B3,'Reference Data'!$A$2:$F$26,3,FALSE),"OK","CHECK"),"MISSING") -> OK | Q3: =IFERROR(IF(E3=VLOOKUP(B3,'Reference Data'!$A$2:$F$26,4,FALSE),"OK","CHECK"),"MISSING") -> OK | R3: =IFERROR(IF(F3=VLOOKUP(B3,'Reference Data'!$A$2:$F$26,5,FALSE),"OK","CHECK"),"MISSING") -> OK | S3: =IF(AND(L3="OK",M3="OK",N3="OK",O3="OK",P3="OK",Q3="OK",R3="OK"),"OK","REVIEW") -> OK
A4: OP003 | B4: REF003 | C4: Mumbai | D4: Operations | E4: Inventory Review | F4: Packaging Materials | G4: 200 | H4: Completed | I4: 46032 | J4: 46034 | L4: =IF(A4="OP"&TEXT(ROW()-1,"000"),"OK","CHECK") -> OK | M4: =IF(OR(AND(H4="Completed",J4<>""),AND(OR(H4="Pending",H4="In Progress"),J4="")),"OK","CHECK") -> OK | N4: =IFERROR(IF(VLOOKUP(B4,'Reference Data'!$A$2:$F$26,1,FALSE)=B4,"OK","CHECK"),"MISSING") -> OK | O4: =IFERROR(IF(C4=VLOOKUP(B4,'Reference Data'!$A$2:$F$26,2,FALSE),"OK","CHECK"),"MISSING") -> OK | P4: =IFERROR(IF(D4=VLOOKUP(B4,'Reference Data'!$A$2:$F$26,3,FALSE),"OK","CHECK"),"MISSING") -> OK | Q4: =IFERROR(IF(E4=VLOOKUP(B4,'Reference Data'!$A$2:$F$26,4,FALSE),"OK","CHECK"),"MISSING") -> OK | R4: =IFERROR(IF(F4=VLOOKUP(B4,'Reference Data'!$A$2:$F$26,5,FALSE),"OK","CHECK"),"MISSING") -> OK | S4: =IF(AND(L4="OK",M4="OK",N4="OK",O4="OK",P4="OK",Q4="OK",R4="OK"),"OK","REVIEW") -> OK
A5: OP004 | B5: REF004 | C5: Mumbai | D5: Supply Chain | E5: Material Request | F5: Raw Materials | G5: 150 | H5: Completed | I5: 46035 | J5: 46036 | L5: =IF(A5="OP"&TEXT(ROW()-1,"000"),"OK","CHECK") -> OK | M5: =IF(OR(AND(H5="Completed",J5<>""),AND(OR(H5="Pending",H5="In Progress"),J5="")),"OK","CHECK") -> OK | N5: =IFERROR(IF(VLOOKUP(B5,'Reference Data'!$A$2:$F$26,1,FALSE)=B5,"OK","CHECK"),"MISSING") -> OK | O5: =IFERROR(IF(C5=VLOOKUP(B5,'Reference Data'!$A$2:$F$26,2,FALSE),"OK","CHECK"),"MISSING") -> OK | P5: =IFERROR(IF(D5=VLOOKUP(B5,'Reference Data'!$A$2:$F$26,3,FALSE),"OK","CHECK"),"MISSING") -> OK | Q5: =IFERROR(IF(E5=VLOOKUP(B5,'Reference Data'!$A$2:$F$26,4,FALSE),"OK","CHECK"),"MISSING") -> OK | R5: =IFERROR(IF(F5=VLOOKUP(B5,'Reference Data'!$A$2:$F$26,5,FALSE),"OK","CHECK"),"MISSING") -> OK | S5: =IF(AND(L5="OK",M5="OK",N5="OK",O5="OK",P5="OK",Q5="OK",R5="OK"),"OK","REVIEW") -> OK
A6: OP005 | B6: REF005 | C6: Pune | D6: Operations | E6: Shipment Processing | F6: Finished Goods | G6: 75 | H6: Completed | I6: 46037 | J6: 46038 | L6: =IF(A6="OP"&TEXT(ROW()-1,"000"),"OK","CHECK") -> OK | M6: =IF(OR(AND(H6="Completed",J6<>""),AND(OR(H6="Pending",H6="In Progress"),J6="")),"OK","CHECK") -> OK | N6: =IFERROR(IF(VLOOKUP(B6,'Reference Data'!$A$2:$F$26,1,FALSE)=B6,"OK","CHECK"),"MISSING") -> OK | O6: =IFERROR(IF(C6=VLOOKUP(B6,'Reference Data'!$A$2:$F$26,2,FALSE),"OK","CHECK"),"MISSING") -> OK | P6: =IFERROR(IF(D6=VLOOKUP(B6,'Reference Data'!$A$2:$F$26,3,FALSE),"OK","CHECK"),"MISSING") -> OK | Q6: =IFERROR(IF(E6=VLOOKUP(B6,'Reference Data'!$A$2:$F$26,4,FALSE),"OK","CHECK"),"MISSING") -> OK | R6: =IFERROR(IF(F6=VLOOKUP(B6,'Reference Data'!$A$2:$F$26,5,FALSE),"OK","CHECK"),"MISSING") -> OK | S6: =IF(AND(L6="OK",M6="OK",N6="OK",O6="OK",P6="OK",Q6="OK",R6="OK"),"OK","REVIEW") -> OK
A7: OP006 | B7: REF006 | C7: Pune | D7: Quality | E7: Quality Inspection | F7: Components | G7: 90 | H7: In Progress | I7: 46040 | L7: =IF(A7="OP"&TEXT(ROW()-1,"000"),"OK","CHECK") -> OK | M7: =IF(OR(AND(H7="Completed",J7<>""),AND(OR(H7="Pending",H7="In Progress"),J7="")),"OK","CHECK") -> OK | N7: =IFERROR(IF(VLOOKUP(B7,'Reference Data'!$A$2:$F$26,1,FALSE)=B7,"OK","CHECK"),"MISSING") -> OK | O7: =IFERROR(IF(C7=VLOOKUP(B7,'Reference Data'!$A$2:$F$26,2,FALSE),"OK","CHECK"),"MISSING") -> OK | P7: =IFERROR(IF(D7=VLOOKUP(B7,'Reference Data'!$A$2:$F$26,3,FALSE),"OK","CHECK"),"MISSING") -> OK | Q7: =IFERROR(IF(E7=VLOOKUP(B7,'Reference Data'!$A$2:$F$26,4,FALSE),"OK","CHECK"),"MISSING") -> OK | R7: =IFERROR(IF(F7=VLOOKUP(B7,'Reference Data'!$A$2:$F$26,5,FALSE),"OK","CHECK"),"MISSING") -> OK | S7: =IF(AND(L7="OK",M7="OK",N7="OK",O7="OK",P7="OK",Q7="OK",R7="OK"),"OK","REVIEW") -> OK
A8: OP007 | B8: REF007 | C8: Bengaluru | D8: Operations | E8: Equipment Inspection | F8: Equipment | G8: 12 | H8: Completed | I8: 46042 | J8: 46043 | L8: =IF(A8="OP"&TEXT(ROW()-1,"000"),"OK","CHECK") -> OK | M8: =IF(OR(AND(H8="Completed",J8<>""),AND(OR(H8="Pending",H8="In Progress"),J8="")),"OK","CHECK") -> OK | N8: =IFERROR(IF(VLOOKUP(B8,'Reference Data'!$A$2:$F$26,1,FALSE)=B8,"OK","CHECK"),"MISSING") -> OK | O8: =IFERROR(IF(C8=VLOOKUP(B8,'Reference Data'!$A$2:$F$26,2,FALSE),"OK","CHECK"),"MISSING") -> OK | P8: =IFERROR(IF(D8=VLOOKUP(B8,'Reference Data'!$A$2:$F$26,3,FALSE),"OK","CHECK"),"MISSING") -> OK | Q8: =IFERROR(IF(E8=VLOOKUP(B8,'Reference Data'!$A$2:$F$26,4,FALSE),"OK","CHECK"),"MISSING") -> OK | R8: =IFERROR(IF(F8=VLOOKUP(B8,'Reference Data'!$A$2:$F$26,5,FALSE),"OK","CHECK"),"MISSING") -> OK | S8: =IF(AND(L8="OK",M8="OK",N8="OK",O8="OK",P8="OK",Q8="OK",R8="OK"),"OK","REVIEW") -> OK
A9: OP008 | B9: REF008 | C9: Bengaluru | D9: Maintenance | E9: Equipment Inspection | F9: Equipment | G9: 8 | H9: Completed | I9: 46045 | J9: 46046 | L9: =IF(A9="OP"&TEXT(ROW()-1,"000"),"OK","CHECK") -> OK | M9: =IF(OR(AND(H9="Completed",J9<>""),AND(OR(H9="Pending",H9="In Progress"),J9="")),"OK","CHECK") -> OK | N9: =IFERROR(IF(VLOOKUP(B9,'Reference Data'!$A$2:$F$26,1,FALSE)=B9,"OK","CHECK"),"MISSING") -> OK | O9: =IFERROR(IF(C9=VLOOKUP(B9,'Reference Data'!$A$2:$F$26,2,FALSE),"OK","CHECK"),"MISSING") -> OK | P9: =IFERROR(IF(D9=VLOOKUP(B9,'Reference Data'!$A$2:$F$26,3,FALSE),"OK","CHECK"),"MISSING") -> OK | Q9: =IFERROR(IF(E9=VLOOKUP(B9,'Reference Data'!$A$2:$F$26,4,FALSE),"OK","CHECK"),"MISSING") -> OK | R9: =IFERROR(IF(F9=VLOOKUP(B9,'Reference Data'!$A$2:$F$26,5,FALSE),"OK","CHECK"),"MISSING") -> OK | S9: =IF(AND(L9="OK",M9="OK",N9="OK",O9="OK",P9="OK",Q9="OK",R9="OK"),"OK","REVIEW") -> OK
A10: OP009 | B10: REF009 | C10: Hyderabad | D10: Supply Chain | E10: Material Request | F10: Components | G10: 175 | H10: Completed | I10: 46048 | J10: 46050 | L10: =IF(A10="OP"&TEXT(ROW()-1,"000"),"OK","CHECK") -> OK | M10: =IF(OR(AND(H10="Completed",J10<>""),AND(OR(H10="Pending",H10="In Progress"),J10="")),"OK","CHECK") -> OK | N10: =IFERROR(IF(VLOOKUP(B10,'Reference Data'!$A$2:$F$26,1,FALSE)=B10,"OK","CHECK"),"MISSING") -> OK | O10: =IFERROR(IF(C10=VLOOKUP(B10,'Reference Data'!$A$2:$F$26,2,FALSE),"OK","CHECK"),"MISSING") -> OK | P10: =IFERROR(IF(D10=VLOOKUP(B10,'Reference Data'!$A$2:$F$26,3,FALSE),"OK","CHECK"),"MISSING") -> OK | Q10: =IFERROR(IF(E10=VLOOKUP(B10,'Reference Data'!$A$2:$F$26,4,FALSE),"OK","CHECK"),"MISSING") -> OK | R10: =IFERROR(IF(F10=VLOOKUP(B10,'Reference Data'!$A$2:$F$26,5,FALSE),"OK","CHECK"),"MISSING") -> OK | S10: =IF(AND(L10="OK",M10="OK",N10="OK",O10="OK",P10="OK",Q10="OK",R10="OK"),"OK","REVIEW") -> OK
A11: OP010 | B11: REF010 | C11: Hyderabad | D11: Operations | E11: Shipment Processing | F11: Packaging Materials | G11: 110 | H11: Completed | I11: 46050 | J11: 46051 | L11: =IF(A11="OP"&TEXT(ROW()-1,"000"),"OK","CHECK") -> OK | M11: =IF(OR(AND(H11="Completed",J11<>""),AND(OR(H11="Pending",H11="In Progress"),J11="")),"OK","CHECK") -> OK | N11: =IFERROR(IF(VLOOKUP(B11,'Reference Data'!$A$2:$F$26,1,FALSE)=B11,"OK","CHECK"),"MISSING") -> OK | O11: =IFERROR(IF(C11=VLOOKUP(B11,'Reference Data'!$A$2:$F$26,2,FALSE),"OK","CHECK"),"MISSING") -> OK | P11: =IFERROR(IF(D11=VLOOKUP(B11,'Reference Data'!$A$2:$F$26,3,FALSE),"OK","CHECK"),"MISSING") -> OK | Q11: =IFERROR(IF(E11=VLOOKUP(B11,'Reference Data'!$A$2:$F$26,4,FALSE),"OK","CHECK"),"MISSING") -> OK | R11: =IFERROR(IF(F11=VLOOKUP(B11,'Reference Data'!$A$2:$F$26,5,FALSE),"OK","CHECK"),"MISSING") -> OK | S11: =IF(AND(L11="OK",M11="OK",N11="OK",O11="OK",P11="OK",Q11="OK",R11="OK"),"OK","REVIEW") -> OK
A12: OP011 | B12: REF011 | C12: Chennai | D12: Quality | E12: Quality Inspection | F12: Raw Materials | G12: 95 | H12: Pending | I12: 46053 | L12: =IF(A12="OP"&TEXT(ROW()-1,"000"),"OK","CHECK") -> OK | M12: =IF(OR(AND(H12="Completed",J12<>""),AND(OR(H12="Pending",H12="In Progress"),J12="")),"OK","CHECK") -> OK | N12: =IFERROR(IF(VLOOKUP(B12,'Reference Data'!$A$2:$F$26,1,FALSE)=B12,"OK","CHECK"),"MISSING") -> OK | O12: =IFERROR(IF(C12=VLOOKUP(B12,'Reference Data'!$A$2:$F$26,2,FALSE),"OK","CHECK"),"MISSING") -> OK | P12: =IFERROR(IF(D12=VLOOKUP(B12,'Reference Data'!$A$2:$F$26,3,FALSE),"OK","CHECK"),"MISSING") -> OK | Q12: =IFERROR(IF(E12=VLOOKUP(B12,'Reference Data'!$A$2:$F$26,4,FALSE),"OK","CHECK"),"MISSING") -> OK | R12: =IFERROR(IF(F12=VLOOKUP(B12,'Reference Data'!$A$2:$F$26,5,FALSE),"OK","CHECK"),"MISSING") -> OK | S12: =IF(AND(L12="OK",M12="OK",N12="OK",O12="OK",P12="OK",Q12="OK",R12="OK"),"OK","REVIEW") -> OK
A13: OP012 | B13: REF012 | C13: Chennai | D13: Operations | E13: Inventory Review | F13: Components | G13: 130 | H13: Completed | I13: 46055 | J13: 46057 | L13: =IF(A13="OP"&TEXT(ROW()-1,"000"),"OK","CHECK") -> OK | M13: =IF(OR(AND(H13="Completed",J13<>""),AND(OR(H13="Pending",H13="In Progress"),J13="")),"OK","CHECK") -> OK | N13: =IFERROR(IF(VLOOKUP(B13,'Reference Data'!$A$2:$F$26,1,FALSE)=B13,"OK","CHECK"),"MISSING") -> OK | O13: =IFERROR(IF(C13=VLOOKUP(B13,'Reference Data'!$A$2:$F$26,2,FALSE),"OK","CHECK"),"MISSING") -> OK | P13: =IFERROR(IF(D13=VLOOKUP(B13,'Reference Data'!$A$2:$F$26,3,FALSE),"OK","CHECK"),"MISSING") -> OK | Q13: =IFERROR(IF(E13=VLOOKUP(B13,'Reference Data'!$A$2:$F$26,4,FALSE),"OK","CHECK"),"MISSING") -> OK | R13: =IFERROR(IF(F13=VLOOKUP(B13,'Reference Data'!$A$2:$F$26,5,FALSE),"OK","CHECK"),"MISSING") -> OK | S13: =IF(AND(L13="OK",M13="OK",N13="OK",O13="OK",P13="OK",Q13="OK",R13="OK"),"OK","REVIEW") -> OK
A14: OP013 | B14: REF013 | C14: Delhi | D14: Supply Chain | E14: Material Request | F14: Packaging Materials | G14: 160 | H14: Completed | I14: 46058 | J14: 46059 | L14: =IF(A14="OP"&TEXT(ROW()-1,"000"),"OK","CHECK") -> OK | M14: =IF(OR(AND(H14="Completed",J14<>""),AND(OR(H14="Pending",H14="In Progress"),J14="")),"OK","CHECK") -> OK | N14: =IFERROR(IF(VLOOKUP(B14,'Reference Data'!$A$2:$F$26,1,FALSE)=B14,"OK","CHECK"),"MISSING") -> OK | O14: =IFERROR(IF(C14=VLOOKUP(B14,'Reference Data'!$A$2:$F$26,2,FALSE),"OK","CHECK"),"MISSING") -> OK | P14: =IFERROR(IF(D14=VLOOKUP(B14,'Reference Data'!$A$2:$F$26,3,FALSE),"OK","CHECK"),"MISSING") -> OK | Q14: =IFERROR(IF(E14=VLOOKUP(B14,'Reference Data'!$A$2:$F$26,4,FALSE),"OK","CHECK"),"MISSING") -> OK | R14: =IFERROR(IF(F14=VLOOKUP(B14,'Reference Data'!$A$2:$F$26,5,FALSE),"OK","CHECK"),"MISSING") -> OK | S14: =IF(AND(L14="OK",M14="OK",N14="OK",O14="OK",P14="OK",Q14="OK",R14="OK"),"OK","REVIEW") -> OK
A15: OP014 | B15: REF014 | C15: Delhi | D15: Operations | E15: Shipment Processing | F15: Finished Goods | G15: 70 | H15: Completed | I15: 46061 | J15: 46062 | L15: =IF(A15="OP"&TEXT(ROW()-1,"000"),"OK","CHECK") -> OK | M15: =IF(OR(AND(H15="Completed",J15<>""),AND(OR(H15="Pending",H15="In Progress"),J15="")),"OK","CHECK") -> OK | N15: =IFERROR(IF(VLOOKUP(B15,'Reference Data'!$A$2:$F$26,1,FALSE)=B15,"OK","CHECK"),"MISSING") -> OK | O15: =IFERROR(IF(C15=VLOOKUP(B15,'Reference Data'!$A$2:$F$26,2,FALSE),"OK","CHECK"),"MISSING") -> OK | P15: =IFERROR(IF(D15=VLOOKUP(B15,'Reference Data'!$A$2:$F$26,3,FALSE),"OK","CHECK"),"MISSING") -> OK | Q15: =IFERROR(IF(E15=VLOOKUP(B15,'Reference Data'!$A$2:$F$26,4,FALSE),"OK","CHECK"),"MISSING") -> OK | R15: =IFERROR(IF(F15=VLOOKUP(B15,'Reference Data'!$A$2:$F$26,5,FALSE),"OK","CHECK"),"MISSING") -> OK | S15: =IF(AND(L15="OK",M15="OK",N15="OK",O15="OK",P15="OK",Q15="OK",R15="OK"),"OK","REVIEW") -> OK
A16: OP015 | B16: REF015 | C16: Kolkata | D16: Maintenance | E16: Equipment Inspection | F16: Equipment | G16: 10 | H16: Completed | I16: 46063 | J16: 46065 | L16: =IF(A16="OP"&TEXT(ROW()-1,"000"),"OK","CHECK") -> OK | M16: =IF(OR(AND(H16="Completed",J16<>""),AND(OR(H16="Pending",H16="In Progress"),J16="")),"OK","CHECK") -> OK | N16: =IFERROR(IF(VLOOKUP(B16,'Reference Data'!$A$2:$F$26,1,FALSE)=B16,"OK","CHECK"),"MISSING") -> OK | O16: =IFERROR(IF(C16=VLOOKUP(B16,'Reference Data'!$A$2:$F$26,2,FALSE),"OK","CHECK"),"MISSING") -> OK | P16: =IFERROR(IF(D16=VLOOKUP(B16,'Reference Data'!$A$2:$F$26,3,FALSE),"OK","CHECK"),"MISSING") -> OK | Q16: =IFERROR(IF(E16=VLOOKUP(B16,'Reference Data'!$A$2:$F$26,4,FALSE),"OK","CHECK"),"MISSING") -> OK | R16: =IFERROR(IF(F16=VLOOKUP(B16,'Reference Data'!$A$2:$F$26,5,FALSE),"OK","CHECK"),"MISSING") -> OK | S16: =IF(AND(L16="OK",M16="OK",N16="OK",O16="OK",P16="OK",Q16="OK",R16="OK"),"OK","REVIEW") -> OK
A17: OP016 | B17: REF016 | C17: Mumbai | D17: Quality | E17: Quality Inspection | F17: Finished Goods | G17: 100 | H17: Completed | I17: 46066 | J17: 46067 | L17: =IF(A17="OP"&TEXT(ROW()-1,"000"),"OK","CHECK") -> OK | M17: =IF(OR(AND(H17="Completed",J17<>""),AND(OR(H17="Pending",H17="In Progress"),J17="")),"OK","CHECK") -> OK | N17: =IFERROR(IF(VLOOKUP(B17,'Reference Data'!$A$2:$F$26,1,FALSE)=B17,"OK","CHECK"),"MISSING") -> OK | O17: =IFERROR(IF(C17=VLOOKUP(B17,'Reference Data'!$A$2:$F$26,2,FALSE),"OK","CHECK"),"MISSING") -> OK | P17: =IFERROR(IF(D17=VLOOKUP(B17,'Reference Data'!$A$2:$F$26,3,FALSE),"OK","CHECK"),"MISSING") -> OK | Q17: =IFERROR(IF(E17=VLOOKUP(B17,'Reference Data'!$A$2:$F$26,4,FALSE),"OK","CHECK"),"MISSING") -> OK | R17: =IFERROR(IF(F17=VLOOKUP(B17,'Reference Data'!$A$2:$F$26,5,FALSE),"OK","CHECK"),"MISSING") -> OK | S17: =IF(AND(L17="OK",M17="OK",N17="OK",O17="OK",P17="OK",Q17="OK",R17="OK"),"OK","REVIEW") -> OK
A18: OP017 | B18: REF017 | C18: Pune | D18: Supply Chain | E18: Material Request | F18: Raw Materials | G18: 145 | H18: Completed | I18: 46068 | J18: 46069 | L18: =IF(A18="OP"&TEXT(ROW()-1,"000"),"OK","CHECK") -> OK | M18: =IF(OR(AND(H18="Completed",J18<>""),AND(OR(H18="Pending",H18="In Progress"),J18="")),"OK","CHECK") -> OK | N18: =IFERROR(IF(VLOOKUP(B18,'Reference Data'!$A$2:$F$26,1,FALSE)=B18,"OK","CHECK"),"MISSING") -> OK | O18: =IFERROR(IF(C18=VLOOKUP(B18,'Reference Data'!$A$2:$F$26,2,FALSE),"OK","CHECK"),"MISSING") -> OK | P18: =IFERROR(IF(D18=VLOOKUP(B18,'Reference Data'!$A$2:$F$26,3,FALSE),"OK","CHECK"),"MISSING") -> OK | Q18: =IFERROR(IF(E18=VLOOKUP(B18,'Reference Data'!$A$2:$F$26,4,FALSE),"OK","CHECK"),"MISSING") -> OK | R18: =IFERROR(IF(F18=VLOOKUP(B18,'Reference Data'!$A$2:$F$26,5,FALSE),"OK","CHECK"),"MISSING") -> OK | S18: =IF(AND(L18="OK",M18="OK",N18="OK",O18="OK",P18="OK",Q18="OK",R18="OK"),"OK","REVIEW") -> OK
A19: OP018 | B19: REF018 | C19: Bengaluru | D19: Operations | E19: Inventory Review | F19: Components | G19: 115 | H19: In Progress | I19: 46071 | L19: =IF(A19="OP"&TEXT(ROW()-1,"000"),"OK","CHECK") -> OK | M19: =IF(OR(AND(H19="Completed",J19<>""),AND(OR(H19="Pending",H19="In Progress"),J19="")),"OK","CHECK") -> OK | N19: =IFERROR(IF(VLOOKUP(B19,'Reference Data'!$A$2:$F$26,1,FALSE)=B19,"OK","CHECK"),"MISSING") -> OK | O19: =IFERROR(IF(C19=VLOOKUP(B19,'Reference Data'!$A$2:$F$26,2,FALSE),"OK","CHECK"),"MISSING") -> OK | P19: =IFERROR(IF(D19=VLOOKUP(B19,'Reference Data'!$A$2:$F$26,3,FALSE),"OK","CHECK"),"MISSING") -> OK | Q19: =IFERROR(IF(E19=VLOOKUP(B19,'Reference Data'!$A$2:$F$26,4,FALSE),"OK","CHECK"),"MISSING") -> OK | R19: =IFERROR(IF(F19=VLOOKUP(B19,'Reference Data'!$A$2:$F$26,5,FALSE),"OK","CHECK"),"MISSING") -> OK | S19: =IF(AND(L19="OK",M19="OK",N19="OK",O19="OK",P19="OK",Q19="OK",R19="OK"),"OK","REVIEW") -> OK
A20: OP019 | B20: REF019 | C20: Hyderabad | D20: Quality | E20: Quality Inspection | F20: Packaging Materials | G20: 80 | H20: Completed | I20: 46073 | J20: 46074 | L20: =IF(A20="OP"&TEXT(ROW()-1,"000"),"OK","CHECK") -> OK | M20: =IF(OR(AND(H20="Completed",J20<>""),AND(OR(H20="Pending",H20="In Progress"),J20="")),"OK","CHECK") -> OK | N20: =IFERROR(IF(VLOOKUP(B20,'Reference Data'!$A$2:$F$26,1,FALSE)=B20,"OK","CHECK"),"MISSING") -> OK | O20: =IFERROR(IF(C20=VLOOKUP(B20,'Reference Data'!$A$2:$F$26,2,FALSE),"OK","CHECK"),"MISSING") -> OK | P20: =IFERROR(IF(D20=VLOOKUP(B20,'Reference Data'!$A$2:$F$26,3,FALSE),"OK","CHECK"),"MISSING") -> OK | Q20: =IFERROR(IF(E20=VLOOKUP(B20,'Reference Data'!$A$2:$F$26,4,FALSE),"OK","CHECK"),"MISSING") -> OK | R20: =IFERROR(IF(F20=VLOOKUP(B20,'Reference Data'!$A$2:$F$26,5,FALSE),"OK","CHECK"),"MISSING") -> OK | S20: =IF(AND(L20="OK",M20="OK",N20="OK",O20="OK",P20="OK",Q20="OK",R20="OK"),"OK","REVIEW") -> OK
A21: OP020 | B21: REF020 | C21: Chennai | D21: Supply Chain | E21: Material Request | F21: Finished Goods | G21: 125 | H21: Completed | I21: 46076 | J21: 46077 | L21: =IF(A21="OP"&TEXT(ROW()-1,"000"),"OK","CHECK") -> OK | M21: =IF(OR(AND(H21="Completed",J21<>""),AND(OR(H21="Pending",H21="In Progress"),J21="")),"OK","CHECK") -> OK | N21: =IFERROR(IF(VLOOKUP(B21,'Reference Data'!$A$2:$F$26,1,FALSE)=B21,"OK","CHECK"),"MISSING") -> OK | O21: =IFERROR(IF(C21=VLOOKUP(B21,'Reference Data'!$A$2:$F$26,2,FALSE),"OK","CHECK"),"MISSING") -> OK | P21: =IFERROR(IF(D21=VLOOKUP(B21,'Reference Data'!$A$2:$F$26,3,FALSE),"OK","CHECK"),"MISSING") -> OK | Q21: =IFERROR(IF(E21=VLOOKUP(B21,'Reference Data'!$A$2:$F$26,4,FALSE),"OK","CHECK"),"MISSING") -> OK | R21: =IFERROR(IF(F21=VLOOKUP(B21,'Reference Data'!$A$2:$F$26,5,FALSE),"OK","CHECK"),"MISSING") -> OK | S21: =IF(AND(L21="OK",M21="OK",N21="OK",O21="OK",P21="OK",Q21="OK",R21="OK"),"OK","REVIEW") -> OK
A22: OP021 | B22: REF021 | C22: Delhi | D22: Quality | E22: Quality Inspection | F22: Components | G22: 105 | H22: Completed | I22: 46079 | J22: 46081 | L22: =IF(A22="OP"&TEXT(ROW()-1,"000"),"OK","CHECK") -> OK | M22: =IF(OR(AND(H22="Completed",J22<>""),AND(OR(H22="Pending",H22="In Progress"),J22="")),"OK","CHECK") -> OK | N22: =IFERROR(IF(VLOOKUP(B22,'Reference Data'!$A$2:$F$26,1,FALSE)=B22,"OK","CHECK"),"MISSING") -> OK | O22: =IFERROR(IF(C22=VLOOKUP(B22,'Reference Data'!$A$2:$F$26,2,FALSE),"OK","CHECK"),"MISSING") -> OK | P22: =IFERROR(IF(D22=VLOOKUP(B22,'Reference Data'!$A$2:$F$26,3,FALSE),"OK","CHECK"),"MISSING") -> OK | Q22: =IFERROR(IF(E22=VLOOKUP(B22,'Reference Data'!$A$2:$F$26,4,FALSE),"OK","CHECK"),"MISSING") -> OK | R22: =IFERROR(IF(F22=VLOOKUP(B22,'Reference Data'!$A$2:$F$26,5,FALSE),"OK","CHECK"),"MISSING") -> OK | S22: =IF(AND(L22="OK",M22="OK",N22="OK",O22="OK",P22="OK",Q22="OK",R22="OK"),"OK","REVIEW") -> OK
A23: OP022 | B23: REF022 | C23: Kolkata | D23: Supply Chain | E23: Material Request | F23: Components | G23: 135 | H23: Completed | I23: 46081 | J23: 46082 | L23: =IF(A23="OP"&TEXT(ROW()-1,"000"),"OK","CHECK") -> OK | M23: =IF(OR(AND(H23="Completed",J23<>""),AND(OR(H23="Pending",H23="In Progress"),J23="")),"OK","CHECK") -> OK | N23: =IFERROR(IF(VLOOKUP(B23,'Reference Data'!$A$2:$F$26,1,FALSE)=B23,"OK","CHECK"),"MISSING") -> OK | O23: =IFERROR(IF(C23=VLOOKUP(B23,'Reference Data'!$A$2:$F$26,2,FALSE),"OK","CHECK"),"MISSING") -> OK | P23: =IFERROR(IF(D23=VLOOKUP(B23,'Reference Data'!$A$2:$F$26,3,FALSE),"OK","CHECK"),"MISSING") -> OK | Q23: =IFERROR(IF(E23=VLOOKUP(B23,'Reference Data'!$A$2:$F$26,4,FALSE),"OK","CHECK"),"MISSING") -> OK | R23: =IFERROR(IF(F23=VLOOKUP(B23,'Reference Data'!$A$2:$F$26,5,FALSE),"OK","CHECK"),"MISSING") -> OK | S23: =IF(AND(L23="OK",M23="OK",N23="OK",O23="OK",P23="OK",Q23="OK",R23="OK"),"OK","REVIEW") -> OK
A24: OP023 | B24: REF023 | C24: Mumbai | D24: Maintenance | E24: Equipment Inspection | F24: Equipment | G24: 9 | H24: Pending | I24: 46084 | L24: =IF(A24="OP"&TEXT(ROW()-1,"000"),"OK","CHECK") -> OK | M24: =IF(OR(AND(H24="Completed",J24<>""),AND(OR(H24="Pending",H24="In Progress"),J24="")),"OK","CHECK") -> OK | N24: =IFERROR(IF(VLOOKUP(B24,'Reference Data'!$A$2:$F$26,1,FALSE)=B24,"OK","CHECK"),"MISSING") -> OK | O24: =IFERROR(IF(C24=VLOOKUP(B24,'Reference Data'!$A$2:$F$26,2,FALSE),"OK","CHECK"),"MISSING") -> OK | P24: =IFERROR(IF(D24=VLOOKUP(B24,'Reference Data'!$A$2:$F$26,3,FALSE),"OK","CHECK"),"MISSING") -> OK | Q24: =IFERROR(IF(E24=VLOOKUP(B24,'Reference Data'!$A$2:$F$26,4,FALSE),"OK","CHECK"),"MISSING") -> OK | R24: =IFERROR(IF(F24=VLOOKUP(B24,'Reference Data'!$A$2:$F$26,5,FALSE),"OK","CHECK"),"MISSING") -> OK | S24: =IF(AND(L24="OK",M24="OK",N24="OK",O24="OK",P24="OK",Q24="OK",R24="OK"),"OK","REVIEW") -> OK
A25: OP024 | B25: REF024 | C25: Pune | D25: Operations | E25: Inventory Review | F25: Raw Materials | G25: 180 | H25: Completed | I25: 46086 | J25: 46088 | L25: =IF(A25="OP"&TEXT(ROW()-1,"000"),"OK","CHECK") -> OK | M25: =IF(OR(AND(H25="Completed",J25<>""),AND(OR(H25="Pending",H25="In Progress"),J25="")),"OK","CHECK") -> OK | N25: =IFERROR(IF(VLOOKUP(B25,'Reference Data'!$A$2:$F$26,1,FALSE)=B25,"OK","CHECK"),"MISSING") -> OK | O25: =IFERROR(IF(C25=VLOOKUP(B25,'Reference Data'!$A$2:$F$26,2,FALSE),"OK","CHECK"),"MISSING") -> OK | P25: =IFERROR(IF(D25=VLOOKUP(B25,'Reference Data'!$A$2:$F$26,3,FALSE),"OK","CHECK"),"MISSING") -> OK | Q25: =IFERROR(IF(E25=VLOOKUP(B25,'Reference Data'!$A$2:$F$26,4,FALSE),"OK","CHECK"),"MISSING") -> OK | R25: =IFERROR(IF(F25=VLOOKUP(B25,'Reference Data'!$A$2:$F$26,5,FALSE),"OK","CHECK"),"MISSING") -> OK | S25: =IF(AND(L25="OK",M25="OK",N25="OK",O25="OK",P25="OK",Q25="OK",R25="OK"),"OK","REVIEW") -> OK
A26: OP025 | B26: REF025 | C26: Bengaluru | D26: Quality | E26: Quality Inspection | F26: Finished Goods | G26: 88 | H26: Completed | I26: 46089 | J26: 46090 | L26: =IF(A26="OP"&TEXT(ROW()-1,"000"),"OK","CHECK") -> OK | M26: =IF(OR(AND(H26="Completed",J26<>""),AND(OR(H26="Pending",H26="In Progress"),J26="")),"OK","CHECK") -> OK | N26: =IFERROR(IF(VLOOKUP(B26,'Reference Data'!$A$2:$F$26,1,FALSE)=B26,"OK","CHECK"),"MISSING") -> OK | O26: =IFERROR(IF(C26=VLOOKUP(B26,'Reference Data'!$A$2:$F$26,2,FALSE),"OK","CHECK"),"MISSING") -> OK | P26: =IFERROR(IF(D26=VLOOKUP(B26,'Reference Data'!$A$2:$F$26,3,FALSE),"OK","CHECK"),"MISSING") -> OK | Q26: =IFERROR(IF(E26=VLOOKUP(B26,'Reference Data'!$A$2:$F$26,4,FALSE),"OK","CHECK"),"MISSING") -> OK | R26: =IFERROR(IF(F26=VLOOKUP(B26,'Reference Data'!$A$2:$F$26,5,FALSE),"OK","CHECK"),"MISSING") -> OK | S26: =IF(AND(L26="OK",M26="OK",N26="OK",O26="OK",P26="OK",Q26="OK",R26="OK"),"OK","REVIEW") -> OK
A27: OP026 | B27: REF001 | C27: Kolkata | D27: Operations | E27: Inventory Review | F27: Raw Materials | G27: 140 | H27: Completed | I27: 46092 | J27: 46093 | L27: =IF(A27="OP"&TEXT(ROW()-1,"000"),"OK","CHECK") -> OK | M27: =IF(OR(AND(H27="Completed",J27<>""),AND(OR(H27="Pending",H27="In Progress"),J27="")),"OK","CHECK") -> OK | N27: =IFERROR(IF(VLOOKUP(B27,'Reference Data'!$A$2:$F$26,1,FALSE)=B27,"OK","CHECK"),"MISSING") -> OK | O27: =IFERROR(IF(C27=VLOOKUP(B27,'Reference Data'!$A$2:$F$26,2,FALSE),"OK","CHECK"),"MISSING") -> OK | P27: =IFERROR(IF(D27=VLOOKUP(B27,'Reference Data'!$A$2:$F$26,3,FALSE),"OK","CHECK"),"MISSING") -> OK | Q27: =IFERROR(IF(E27=VLOOKUP(B27,'Reference Data'!$A$2:$F$26,4,FALSE),"OK","CHECK"),"MISSING") -> OK | R27: =IFERROR(IF(F27=VLOOKUP(B27,'Reference Data'!$A$2:$F$26,5,FALSE),"OK","CHECK"),"MISSING") -> OK | S27: =IF(AND(L27="OK",M27="OK",N27="OK",O27="OK",P27="OK",Q27="OK",R27="OK"),"OK","REVIEW") -> OK
A28: OP027 | B28: REF002 | C28: Kolkata | D28: Quality | E28: Quality Inspection | F28: Finished Goods | G28: 92 | H28: Completed | I28: 46094 | J28: 46096 | L28: =IF(A28="OP"&TEXT(ROW()-1,"000"),"OK","CHECK") -> OK | M28: =IF(OR(AND(H28="Completed",J28<>""),AND(OR(H28="Pending",H28="In Progress"),J28="")),"OK","CHECK") -> OK | N28: =IFERROR(IF(VLOOKUP(B28,'Reference Data'!$A$2:$F$26,1,FALSE)=B28,"OK","CHECK"),"MISSING") -> OK | O28: =IFERROR(IF(C28=VLOOKUP(B28,'Reference Data'!$A$2:$F$26,2,FALSE),"OK","CHECK"),"MISSING") -> OK | P28: =IFERROR(IF(D28=VLOOKUP(B28,'Reference Data'!$A$2:$F$26,3,FALSE),"OK","CHECK"),"MISSING") -> OK | Q28: =IFERROR(IF(E28=VLOOKUP(B28,'Reference Data'!$A$2:$F$26,4,FALSE),"OK","CHECK"),"MISSING") -> OK | R28: =IFERROR(IF(F28=VLOOKUP(B28,'Reference Data'!$A$2:$F$26,5,FALSE),"OK","CHECK"),"MISSING") -> OK | S28: =IF(AND(L28="OK",M28="OK",N28="OK",O28="OK",P28="OK",Q28="OK",R28="OK"),"OK","REVIEW") -> OK
A29: OP028 | B29: REF003 | C29: Mumbai | D29: Operations | E29: Inventory Review | F29: Packaging Materials | G29: 210 | H29: Completed | I29: 46097 | J29: 46098 | L29: =IF(A29="OP"&TEXT(ROW()-1,"000"),"OK","CHECK") -> OK | M29: =IF(OR(AND(H29="Completed",J29<>""),AND(OR(H29="Pending",H29="In Progress"),J29="")),"OK","CHECK") -> OK | N29: =IFERROR(IF(VLOOKUP(B29,'Reference Data'!$A$2:$F$26,1,FALSE)=B29,"OK","CHECK"),"MISSING") -> OK | O29: =IFERROR(IF(C29=VLOOKUP(B29,'Reference Data'!$A$2:$F$26,2,FALSE),"OK","CHECK"),"MISSING") -> OK | P29: =IFERROR(IF(D29=VLOOKUP(B29,'Reference Data'!$A$2:$F$26,3,FALSE),"OK","CHECK"),"MISSING") -> OK | Q29: =IFERROR(IF(E29=VLOOKUP(B29,'Reference Data'!$A$2:$F$26,4,FALSE),"OK","CHECK"),"MISSING") -> OK | R29: =IFERROR(IF(F29=VLOOKUP(B29,'Reference Data'!$A$2:$F$26,5,FALSE),"OK","CHECK"),"MISSING") -> OK | S29: =IF(AND(L29="OK",M29="OK",N29="OK",O29="OK",P29="OK",Q29="OK",R29="OK"),"OK","REVIEW") -> OK
A30: OP029 | B30: REF004 | C30: Mumbai | D30: Supply Chain | E30: Material Request | F30: Raw Materials | G30: 165 | H30: Pending | I30: 46099 | L30: =IF(A30="OP"&TEXT(ROW()-1,"000"),"OK","CHECK") -> OK | M30: =IF(OR(AND(H30="Completed",J30<>""),AND(OR(H30="Pending",H30="In Progress"),J30="")),"OK","CHECK") -> OK | N30: =IFERROR(IF(VLOOKUP(B30,'Reference Data'!$A$2:$F$26,1,FALSE)=B30,"OK","CHECK"),"MISSING") -> OK | O30: =IFERROR(IF(C30=VLOOKUP(B30,'Reference Data'!$A$2:$F$26,2,FALSE),"OK","CHECK"),"MISSING") -> OK | P30: =IFERROR(IF(D30=VLOOKUP(B30,'Reference Data'!$A$2:$F$26,3,FALSE),"OK","CHECK"),"MISSING") -> OK | Q30: =IFERROR(IF(E30=VLOOKUP(B30,'Reference Data'!$A$2:$F$26,4,FALSE),"OK","CHECK"),"MISSING") -> OK | R30: =IFERROR(IF(F30=VLOOKUP(B30,'Reference Data'!$A$2:$F$26,5,FALSE),"OK","CHECK"),"MISSING") -> OK | S30: =IF(AND(L30="OK",M30="OK",N30="OK",O30="OK",P30="OK",Q30="OK",R30="OK"),"OK","REVIEW") -> OK
A31: OP030 | B31: REF005 | C31: Pune | D31: Operations | E31: Shipment Processing | F31: Finished Goods | G31: 82 | H31: Completed | I31: 46102 | J31: 46104 | L31: =IF(A31="OP"&TEXT(ROW()-1,"000"),"OK","CHECK") -> OK | M31: =IF(OR(AND(H31="Completed",J31<>""),AND(OR(H31="Pending",H31="In Progress"),J31="")),"OK","CHECK") -> OK | N31: =IFERROR(IF(VLOOKUP(B31,'Reference Data'!$A$2:$F$26,1,FALSE)=B31,"OK","CHECK"),"MISSING") -> OK | O31: =IFERROR(IF(C31=VLOOKUP(B31,'Reference Data'!$A$2:$F$26,2,FALSE),"OK","CHECK"),"MISSING") -> OK | P31: =IFERROR(IF(D31=VLOOKUP(B31,'Reference Data'!$A$2:$F$26,3,FALSE),"OK","CHECK"),"MISSING") -> OK | Q31: =IFERROR(IF(E31=VLOOKUP(B31,'Reference Data'!$A$2:$F$26,4,FALSE),"OK","CHECK"),"MISSING") -> OK | R31: =IFERROR(IF(F31=VLOOKUP(B31,'Reference Data'!$A$2:$F$26,5,FALSE),"OK","CHECK"),"MISSING") -> OK | S31: =IF(AND(L31="OK",M31="OK",N31="OK",O31="OK",P31="OK",Q31="OK",R31="OK"),"OK","REVIEW") -> OK
A32: OP031 | B32: REF006 | C32: Pune | D32: Quality | E32: Quality Inspection | F32: Components | G32: 95 | H32: In Progress | I32: 46104 | L32: =IF(A32="OP"&TEXT(ROW()-1,"000"),"OK","CHECK") -> OK | M32: =IF(OR(AND(H32="Completed",J32<>""),AND(OR(H32="Pending",H32="In Progress"),J32="")),"OK","CHECK") -> OK | N32: =IFERROR(IF(VLOOKUP(B32,'Reference Data'!$A$2:$F$26,1,FALSE)=B32,"OK","CHECK"),"MISSING") -> OK | O32: =IFERROR(IF(C32=VLOOKUP(B32,'Reference Data'!$A$2:$F$26,2,FALSE),"OK","CHECK"),"MISSING") -> OK | P32: =IFERROR(IF(D32=VLOOKUP(B32,'Reference Data'!$A$2:$F$26,3,FALSE),"OK","CHECK"),"MISSING") -> OK | Q32: =IFERROR(IF(E32=VLOOKUP(B32,'Reference Data'!$A$2:$F$26,4,FALSE),"OK","CHECK"),"MISSING") -> OK | R32: =IFERROR(IF(F32=VLOOKUP(B32,'Reference Data'!$A$2:$F$26,5,FALSE),"OK","CHECK"),"MISSING") -> OK | S32: =IF(AND(L32="OK",M32="OK",N32="OK",O32="OK",P32="OK",Q32="OK",R32="OK"),"OK","REVIEW") -> OK
A33: OP032 | B33: REF007 | C33: Bengaluru | D33: Operations | E33: Equipment Inspection | F33: Equipment | G33: 14 | H33: Completed | I33: 46107 | J33: 46108 | L33: =IF(A33="OP"&TEXT(ROW()-1,"000"),"OK","CHECK") -> OK | M33: =IF(OR(AND(H33="Completed",J33<>""),AND(OR(H33="Pending",H33="In Progress"),J33="")),"OK","CHECK") -> OK | N33: =IFERROR(IF(VLOOKUP(B33,'Reference Data'!$A$2:$F$26,1,FALSE)=B33,"OK","CHECK"),"MISSING") -> OK | O33: =IFERROR(IF(C33=VLOOKUP(B33,'Reference Data'!$A$2:$F$26,2,FALSE),"OK","CHECK"),"MISSING") -> OK | P33: =IFERROR(IF(D33=VLOOKUP(B33,'Reference Data'!$A$2:$F$26,3,FALSE),"OK","CHECK"),"MISSING") -> OK | Q33: =IFERROR(IF(E33=VLOOKUP(B33,'Reference Data'!$A$2:$F$26,4,FALSE),"OK","CHECK"),"MISSING") -> OK | R33: =IFERROR(IF(F33=VLOOKUP(B33,'Reference Data'!$A$2:$F$26,5,FALSE),"OK","CHECK"),"MISSING") -> OK | S33: =IF(AND(L33="OK",M33="OK",N33="OK",O33="OK",P33="OK",Q33="OK",R33="OK"),"OK","REVIEW") -> OK
A34: OP033 | B34: REF008 | C34: Bengaluru | D34: Maintenance | E34: Equipment Inspection | F34: Equipment | G34: 11 | H34: Completed | I34: 46110 | J34: 46112 | L34: =IF(A34="OP"&TEXT(ROW()-1,"000"),"OK","CHECK") -> OK | M34: =IF(OR(AND(H34="Completed",J34<>""),AND(OR(H34="Pending",H34="In Progress"),J34="")),"OK","CHECK") -> OK | N34: =IFERROR(IF(VLOOKUP(B34,'Reference Data'!$A$2:$F$26,1,FALSE)=B34,"OK","CHECK"),"MISSING") -> OK | O34: =IFERROR(IF(C34=VLOOKUP(B34,'Reference Data'!$A$2:$F$26,2,FALSE),"OK","CHECK"),"MISSING") -> OK | P34: =IFERROR(IF(D34=VLOOKUP(B34,'Reference Data'!$A$2:$F$26,3,FALSE),"OK","CHECK"),"MISSING") -> OK | Q34: =IFERROR(IF(E34=VLOOKUP(B34,'Reference Data'!$A$2:$F$26,4,FALSE),"OK","CHECK"),"MISSING") -> OK | R34: =IFERROR(IF(F34=VLOOKUP(B34,'Reference Data'!$A$2:$F$26,5,FALSE),"OK","CHECK"),"MISSING") -> OK | S34: =IF(AND(L34="OK",M34="OK",N34="OK",O34="OK",P34="OK",Q34="OK",R34="OK"),"OK","REVIEW") -> OK
A35: OP034 | B35: REF009 | C35: Hyderabad | D35: Supply Chain | E35: Material Request | F35: Components | G35: 185 | H35: Completed | I35: 46112 | J35: 46113 | L35: =IF(A35="OP"&TEXT(ROW()-1,"000"),"OK","CHECK") -> OK | M35: =IF(OR(AND(H35="Completed",J35<>""),AND(OR(H35="Pending",H35="In Progress"),J35="")),"OK","CHECK") -> OK | N35: =IFERROR(IF(VLOOKUP(B35,'Reference Data'!$A$2:$F$26,1,FALSE)=B35,"OK","CHECK"),"MISSING") -> OK | O35: =IFERROR(IF(C35=VLOOKUP(B35,'Reference Data'!$A$2:$F$26,2,FALSE),"OK","CHECK"),"MISSING") -> OK | P35: =IFERROR(IF(D35=VLOOKUP(B35,'Reference Data'!$A$2:$F$26,3,FALSE),"OK","CHECK"),"MISSING") -> OK | Q35: =IFERROR(IF(E35=VLOOKUP(B35,'Reference Data'!$A$2:$F$26,4,FALSE),"OK","CHECK"),"MISSING") -> OK | R35: =IFERROR(IF(F35=VLOOKUP(B35,'Reference Data'!$A$2:$F$26,5,FALSE),"OK","CHECK"),"MISSING") -> OK | S35: =IF(AND(L35="OK",M35="OK",N35="OK",O35="OK",P35="OK",Q35="OK",R35="OK"),"OK","REVIEW") -> OK
A36: OP035 | B36: REF010 | C36: Hyderabad | D36: Operations | E36: Shipment Processing | F36: Packaging Materials | G36: 115 | H36: Completed | I36: 46115 | J36: 46116 | L36: =IF(A36="OP"&TEXT(ROW()-1,"000"),"OK","CHECK") -> OK | M36: =IF(OR(AND(H36="Completed",J36<>""),AND(OR(H36="Pending",H36="In Progress"),J36="")),"OK","CHECK") -> OK | N36: =IFERROR(IF(VLOOKUP(B36,'Reference Data'!$A$2:$F$26,1,FALSE)=B36,"OK","CHECK"),"MISSING") -> OK | O36: =IFERROR(IF(C36=VLOOKUP(B36,'Reference Data'!$A$2:$F$26,2,FALSE),"OK","CHECK"),"MISSING") -> OK | P36: =IFERROR(IF(D36=VLOOKUP(B36,'Reference Data'!$A$2:$F$26,3,FALSE),"OK","CHECK"),"MISSING") -> OK | Q36: =IFERROR(IF(E36=VLOOKUP(B36,'Reference Data'!$A$2:$F$26,4,FALSE),"OK","CHECK"),"MISSING") -> OK | R36: =IFERROR(IF(F36=VLOOKUP(B36,'Reference Data'!$A$2:$F$26,5,FALSE),"OK","CHECK"),"MISSING") -> OK | S36: =IF(AND(L36="OK",M36="OK",N36="OK",O36="OK",P36="OK",Q36="OK",R36="OK"),"OK","REVIEW") -> OK
A37: OP036 | B37: REF011 | C37: Chennai | D37: Quality | E37: Quality Inspection | F37: Raw Materials | G37: 105 | H37: Completed | I37: 46117 | J37: 46119 | L37: =IF(A37="OP"&TEXT(ROW()-1,"000"),"OK","CHECK") -> OK | M37: =IF(OR(AND(H37="Completed",J37<>""),AND(OR(H37="Pending",H37="In Progress"),J37="")),"OK","CHECK") -> OK | N37: =IFERROR(IF(VLOOKUP(B37,'Reference Data'!$A$2:$F$26,1,FALSE)=B37,"OK","CHECK"),"MISSING") -> OK | O37: =IFERROR(IF(C37=VLOOKUP(B37,'Reference Data'!$A$2:$F$26,2,FALSE),"OK","CHECK"),"MISSING") -> OK | P37: =IFERROR(IF(D37=VLOOKUP(B37,'Reference Data'!$A$2:$F$26,3,FALSE),"OK","CHECK"),"MISSING") -> OK | Q37: =IFERROR(IF(E37=VLOOKUP(B37,'Reference Data'!$A$2:$F$26,4,FALSE),"OK","CHECK"),"MISSING") -> OK | R37: =IFERROR(IF(F37=VLOOKUP(B37,'Reference Data'!$A$2:$F$26,5,FALSE),"OK","CHECK"),"MISSING") -> OK | S37: =IF(AND(L37="OK",M37="OK",N37="OK",O37="OK",P37="OK",Q37="OK",R37="OK"),"OK","REVIEW") -> OK
A38: OP037 | B38: REF012 | C38: Chennai | D38: Operations | E38: Inventory Review | F38: Components | G38: 145 | H38: Pending | I38: 46120 | L38: =IF(A38="OP"&TEXT(ROW()-1,"000"),"OK","CHECK") -> OK | M38: =IF(OR(AND(H38="Completed",J38<>""),AND(OR(H38="Pending",H38="In Progress"),J38="")),"OK","CHECK") -> OK | N38: =IFERROR(IF(VLOOKUP(B38,'Reference Data'!$A$2:$F$26,1,FALSE)=B38,"OK","CHECK"),"MISSING") -> OK | O38: =IFERROR(IF(C38=VLOOKUP(B38,'Reference Data'!$A$2:$F$26,2,FALSE),"OK","CHECK"),"MISSING") -> OK | P38: =IFERROR(IF(D38=VLOOKUP(B38,'Reference Data'!$A$2:$F$26,3,FALSE),"OK","CHECK"),"MISSING") -> OK | Q38: =IFERROR(IF(E38=VLOOKUP(B38,'Reference Data'!$A$2:$F$26,4,FALSE),"OK","CHECK"),"MISSING") -> OK | R38: =IFERROR(IF(F38=VLOOKUP(B38,'Reference Data'!$A$2:$F$26,5,FALSE),"OK","CHECK"),"MISSING") -> OK | S38: =IF(AND(L38="OK",M38="OK",N38="OK",O38="OK",P38="OK",Q38="OK",R38="OK"),"OK","REVIEW") -> OK
A39: OP038 | B39: REF013 | C39: Delhi | D39: Supply Chain | E39: Material Request | F39: Packaging Materials | G39: 175 | H39: Completed | I39: 46123 | J39: 46124 | L39: =IF(A39="OP"&TEXT(ROW()-1,"000"),"OK","CHECK") -> OK | M39: =IF(OR(AND(H39="Completed",J39<>""),AND(OR(H39="Pending",H39="In Progress"),J39="")),"OK","CHECK") -> OK | N39: =IFERROR(IF(VLOOKUP(B39,'Reference Data'!$A$2:$F$26,1,FALSE)=B39,"OK","CHECK"),"MISSING") -> OK | O39: =IFERROR(IF(C39=VLOOKUP(B39,'Reference Data'!$A$2:$F$26,2,FALSE),"OK","CHECK"),"MISSING") -> OK | P39: =IFERROR(IF(D39=VLOOKUP(B39,'Reference Data'!$A$2:$F$26,3,FALSE),"OK","CHECK"),"MISSING") -> OK | Q39: =IFERROR(IF(E39=VLOOKUP(B39,'Reference Data'!$A$2:$F$26,4,FALSE),"OK","CHECK"),"MISSING") -> OK | R39: =IFERROR(IF(F39=VLOOKUP(B39,'Reference Data'!$A$2:$F$26,5,FALSE),"OK","CHECK"),"MISSING") -> OK | S39: =IF(AND(L39="OK",M39="OK",N39="OK",O39="OK",P39="OK",Q39="OK",R39="OK"),"OK","REVIEW") -> OK
A40: OP039 | B40: REF014 | C40: Delhi | D40: Operations | E40: Shipment Processing | F40: Finished Goods | G40: 78 | H40: Completed | I40: 46125 | J40: 46127 | L40: =IF(A40="OP"&TEXT(ROW()-1,"000"),"OK","CHECK") -> OK | M40: =IF(OR(AND(H40="Completed",J40<>""),AND(OR(H40="Pending",H40="In Progress"),J40="")),"OK","CHECK") -> OK | N40: =IFERROR(IF(VLOOKUP(B40,'Reference Data'!$A$2:$F$26,1,FALSE)=B40,"OK","CHECK"),"MISSING") -> OK | O40: =IFERROR(IF(C40=VLOOKUP(B40,'Reference Data'!$A$2:$F$26,2,FALSE),"OK","CHECK"),"MISSING") -> OK | P40: =IFERROR(IF(D40=VLOOKUP(B40,'Reference Data'!$A$2:$F$26,3,FALSE),"OK","CHECK"),"MISSING") -> OK | Q40: =IFERROR(IF(E40=VLOOKUP(B40,'Reference Data'!$A$2:$F$26,4,FALSE),"OK","CHECK"),"MISSING") -> OK | R40: =IFERROR(IF(F40=VLOOKUP(B40,'Reference Data'!$A$2:$F$26,5,FALSE),"OK","CHECK"),"MISSING") -> OK | S40: =IF(AND(L40="OK",M40="OK",N40="OK",O40="OK",P40="OK",Q40="OK",R40="OK"),"OK","REVIEW") -> OK
...

Sheet Reference Data
A1: Reference ID | B1: Facility | C1: Department | D1: Process Type | E1: Item Category | F1: Standard Status
A2: REF001 | B2: Kolkata | C2: Operations | D2: Inventory Review | E2: Raw Materials | F2: Active | I2: Total Reference Records | J2: Unique Refernce IDs
A3: REF002 | B3: Kolkata | C3: Quality | D3: Quality Inspection | E3: Finished Goods | F3: Active | I3: =COUNTA(A2:A26) -> 25 | J3: =SUMPRODUCT(1/COUNTIF(A2:A26,A2:A26)) -> 25
A4: REF003 | B4: Mumbai | C4: Operations | D4: Inventory Review | E4: Packaging Materials | F4: Active
A5: REF004 | B5: Mumbai | C5: Supply Chain | D5: Material Request | E5: Raw Materials | F5: Active
A6: REF005 | B6: Pune | C6: Operations | D6: Shipment Processing | E6: Finished Goods | F6: Active
A7: REF006 | B7: Pune | C7: Quality | D7: Quality Inspection | E7: Components | F7: Active
A8: REF007 | B8: Bengaluru | C8: Operations | D8: Equipment Inspection | E8: Equipment | F8: Active
A9: REF008 | B9: Bengaluru | C9: Maintenance | D9: Equipment Inspection | E9: Equipment | F9: Active
A10: REF009 | B10: Hyderabad | C10: Supply Chain | D10: Material Request | E10: Components | F10: Active
A11: REF010 | B11: Hyderabad | C11: Operations | D11: Shipment Processing | E11: Packaging Materials | F11: Active
A12: REF011 | B12: Chennai | C12: Quality | D12: Quality Inspection | E12: Raw Materials | F12: Active
A13: REF012 | B13: Chennai | C13: Operations | D13: Inventory Review | E13: Components | F13: Active
A14: REF013 | B14: Delhi | C14: Supply Chain | D14: Material Request | E14: Packaging Materials | F14: Active
A15: REF014 | B15: Delhi | C15: Operations | D15: Shipment Processing | E15: Finished Goods | F15: Active
... A26: REF025 | B26: Bengaluru | C26: Quality | D26: Quality Inspection | E26: Finished Goods | F26: Active

Sheet Reference Data Analysis
A3: Items Category | B3: Count of Reference ID
A4: Components | B4: 6
A5: Equipment | B5: 4
A6: Finished Goods | B6: 6
A7: Packaging Materials | B7: 4
A8: Raw Materials | B8: 5
A9: Grand Total | B9: 25

Sheet Operations Data Analysis
A3: Count of Operation ID | B3: Status | H3: KPI
A4: Department | B4: Completed | C4: Pending | D4: In Progress | E4: Grand Total | H4: Total Operations | I4: =COUNTA('Operations Data'!A2:A81) -> 80
A5: Maintenance | B5: 6 | C5: 2 | D5: 1 | E5: 9 | H5: Completed Operations | I5: =COUNTIF('Operations Data'!H2:H81,"Completed") -> 65
A6: Operations | B6: 26 | C6: 1 | D6: 2 | E6: 29 | H6: Pending Operations | I6: =COUNTIF('Operations Data'!H2:H81,"Pending") -> 7
A7: Quality | B7: 15 | C7: 2 | D7: 5 | E7: 22 | H7: In Progress Operations | I7: =COUNTIF('Operations Data'!H2:H81,"In Progress") -> 8
A8: Supply Chain | B8: 18 | C8: 2 | E8: 20 | H8: Completion Rate | I8: =I5/I4 -> 0.8125
A9: Grand Total | B9: 65 | C9: 7 | D9: 8 | E9: 80

Sheet Dashboard
A1: Sales Operations Data Validation & Performance Dashboard
A3: Total Operations | B3: Completed Operations | C3: Pending Operations | D3: In Progress Operations | E3: CompletionRate
A4: 80 | B4: 65 | C4: 7 | D4: 8 | E4: 0.8125
